Workbook

Sheet SA P & L
A1: Profit and Loss | M1: Profit and Loss
A2: Saint Raphael PtyLtd t/a Sanctura | M2: Dr James Laporta Inc
A3: For the month ended 30 November 2025 | M3: For the month ended 30 November 2025
A5: Account | B5: Nov 2025 | C5: Oct 2025 | D5: Sep 2025 | E5: Aug 2025 | F5: Jul 2025 | G5: Jun 2025 | H5: May 2025 | I5: Apr 2025 | J5: Mar 2025 | K5: Year to date | M5: Account | N5: Nov 2025 | O5: Oct 2025 | P5: Sep 2025 | Q5: Aug 2025 | R5: Jul 2025 | S5: Jun 2025 | T5: May 2025 | U5: Apr 2025 | V5: Mar 2025 | W5: Year to date
A7: Trading Income | M7: Trading Income
A8: Interest Income | B8: 297.19 | C8: 225.96 | D8: 223.83 | E8: 325.99 | F8: 309.61 | G8: 233.47 | H8: 491.36 | I8: 606.07 | J8: 885.1 | K8: 3598.58 | M8: Interest Income | N8: 749.63 | O8: 2033.49 | P8: 249.61 | Q8: 1033.9 | R8: 1079.76 | S8: 2521.63 | T8: 2816.02 | U8: 2758.93 | V8: 3079.45 | W8: 16322.42
A9: Other Revenue | B9: 226590.89 | C9: 227857.39 | D9: 232162.92 | E9: 715957.99 | F9: 0 | G9: 0 | H9: 673482.97 | I9: 0 | J9: 0 | K9: 2076052.2 | M9: Sales | N9: 1092297.5 | O9: 1700808.7 | P9: 1506601.2 | Q9: 1457440.2 | R9: 1756178.4 | S9: 1600736.8 | T9: 2363910.7 | U9: 2257106.5 | V9: 2345295.3 | W9: 16080375
A10: Sales | B10: 1571884.9 | C10: 1830943.8 | D10: 1841449.7 | E10: 1842120.9 | F10: 1867679 | G10: 1590706.2 | H10: 1611732.3 | I10: 1878388.4 | J10: 1423966.8 | K10: 15458872 | M10: Total Trading Income | N10: =SUM(N8:N9) -> 1093047.1 | O10: =SUM(O8:O9) -> 1702842.2 | P10: =SUM(P8:P9) -> 1506850.9 | Q10: =SUM(Q8:Q9) -> 1458474.1 | R10: =SUM(R8:R9) -> 1757258.2 | S10: =SUM(S8:S9) -> 1603258.4 | T10: =SUM(T8:T9) -> 2366726.7 | U10: =SUM(U8:U9) -> 2259865.5 | ... W10: =SUM(W8:W9) -> 16096698
A11: Total Trading Income | B11: =SUM(B8:B10) -> 1798773 | C11: =SUM(C8:C10) -> 2059027.1 | D11: =SUM(D8:D10) -> 2073836.4 | E11: =SUM(E8:E10) -> 2558404.9 | F11: =SUM(F8:F10) -> 1867988.6 | G11: =SUM(G8:G10) -> 1590939.7 | H11: =SUM(H8:H10) -> 2285706.6 | I11: =SUM(I8:I10) -> 1878994.4 | ... K11: =SUM(K8:K10) -> 17538523
M12: Cost of Sales
A13: Cost of Sales | M13: Cost of Goods Sold | N13: 418076.09 | O13: 576951.25 | P13: 919714.77 | Q13: 1003861.2 | R13: 771216.25 | S13: 957081.16 | T13: 1337865.4 | U13: 876007.6 | V13: 150446.69 | W13: 7011220.4
A14: Cost of Goods Sold | B14: 138381.17 | C14: 145285.23 | D14: 118177.22 | E14: 110366.18 | F14: 155657.07 | G14: 138604.73 | H14: 191313.04 | I14: 291245.53 | J14: 556561.65 | K14: 1845591.8 | M14: Total Cost of Sales | N14: =N13 -> 418076.09 | O14: =O13 -> 576951.25 | P14: =P13 -> 919714.77 | Q14: =Q13 -> 1003861.2 | R14: =R13 -> 771216.25 | S14: =S13 -> 957081.16 | T14: =T13 -> 1337865.4 | U14: =U13 -> 876007.6 | ... W14: =W13 -> 7011220.4
A15: Total Cost of Sales | B15: =B14 -> 138381.17 | C15: =C14 -> 145285.23 | D15: =D14 -> 118177.22 | E15: =E14 -> 110366.18 | F15: =F14 -> 155657.07 | G15: =G14 -> 138604.73 | H15: =H14 -> 191313.04 | I15: =I14 -> 291245.53 | ... K15: =K14 -> 1845591.8
M16: Gross Profit | N16: =(N10 - N14) -> 674971.05 | O16: =(O10 - O14) -> 1125890.9 | P16: =(P10 - P14) -> 587136.09 | Q16: =(Q10 - Q14) -> 454612.93 | R16: =(R10 - R14) -> 986041.94 | S16: =(S10 - S14) -> 646177.28 | T16: =(T10 - T14) -> 1028861.3 | U16: =(U10 - U14) -> 1383857.9 | ... W16: =(W10 - W14) -> 9085477.5
A17: Gross Profit | B17: =(B11 - B15) -> 1660391.8 | C17: =(C11 - C15) -> 1913741.9 | D17: =(D11 - D15) -> 1955659.2 | E17: =(E11 - E15) -> 2448038.7 | F17: =(F11 - F15) -> 1712331.5 | G17: =(G11 - G15) -> 1452335 | H17: =(H11 - H15) -> 2094393.6 | I17: =(I11 - I15) -> 1587748.9 | ... K17: =(K11 - K15) -> 15692931
M18: Operating Expenses
A19: Operating Expenses | M19: Advertising | N19: 125000 | O19: 125000 | P19: 125000 | Q19: 125000 | R19: 125000 | S19: 125000 | T19: 125000 | U19: 125000 | V19: 125000 | W19: 1125000
A20: Advertising | B20: 53660.37 | C20: 98096.95 | D20: 76471.72 | E20: 85156.51 | F20: 79744.11 | G20: 76913.58 | H20: 124981.47 | I20: 61843.83 | J20: 96761 | K20: 753629.54 | M20: Bank Fees | N20: 24925.86 | O20: 17946.57 | P20: 23125.82 | Q20: 13750.99 | R20: 22209.27 | S20: 29420.87 | T20: 25394.76 | U20: 40612.19 | V20: 35453.59 | W20: 232839.92
A21: Bank Fees | B21: 1422.69 | C21: 773.79 | D21: 1688.74 | E21: 1705.1 | F21: 1801.35 | G21: 1958.28 | H21: 1407.04 | I21: 2097.87 | J21: 713.4 | K21: 13568.26 | M21: Cleaning & Office Expenses | N21: 18934.87 | O21: 25543.65 | P21: 23416.31 | Q21: 36128.42 | R21: 17464.25 | S21: 7346.11 | T21: 15429.66 | U21: 21968.14 | V21: 31499.63 | W21: 197731.04
A22: Casual Wages | B22: 0 | C22: 0 | D22: 0 | E22: 0 | F22: 2000 | G22: 0 | H22: 0 | I22: 18806.54 | J22: 24000 | K22: 44806.54 | M22: Consulting, Accounting & Administrative Fees | N22: 125000 | O22: 132438.32 | P22: 139348.09 | Q22: 165384.62 | R22: 0 | S22: 4400 | T22: 5400 | U22: 8100 | V22: 0 | W22: 580071.03
A23: Cleaning & Office Expenses | B23: 2550.22 | C23: 14706.18 | D23: 11153.76 | E23: 12754.31 | F23: 8488.79 | G23: 9645.7 | H23: 9122.58 | I23: 20457.15 | J23: 7152.99 | K23: 96031.68 | M23: Depreciation | N23: 26979.19 | O23: 27018.34 | P23: 26979.18 | Q23: 27018.33 | R23: 27018.29 | S23: 26979.22 | T23: 27018.32 | U23: 26979.18 | V23: 27018.32 | W23: 243008.37
A24: Consulting, Accounting & Administrative Fees | B24: 22945 | C24: 23950.39 | D24: 9542 | E24: 9542 | F24: 31669.5 | G24: 10571.25 | H24: 9542 | I24: 9542 | J24: 11094.5 | K24: 138398.64 | M24: Insurance | N24: 34962.81 | O24: 34962.81 | P24: 34962.81 | Q24: 51236.87 | R24: 18688.75 | S24: 18682.66 | T24: 18682.66 | U24: 18682.66 | V24: 18682.66 | W24: 249544.69
A25: Depreciation | B25: 277684.38 | C25: 277684.36 | D25: 277684.32 | E25: 277684.31 | F25: 277746.87 | G25: 277749.47 | H25: 277749.47 | I25: 277749.52 | J25: 277749.45 | K25: 2499482.1 | M25: MGNT - Accounting and other related services | N25: 29636.09 | O25: 0 | P25: 19735.84 | Q25: 0 | R25: 0 | S25: 23050.61 | T25: 34040.31 | U25: 32502.33 | V25: 33772.25 | W25: 172737.43
A26: Donations | B26: 0 | C26: 0 | D26: 0 | E26: 0 | F26: 0 | G26: 7000 | H26: 0 | I26: 0 | J26: 0 | K26: 7000 | M26: MGNT - Equipment rental | N26: 10000 | O26: 0 | P26: 10000 | Q26: 0 | R26: 0 | S26: 30000 | T26: 30000 | U26: 30000 | V26: 30000 | W26: 140000
A27: Legal expenses | B27: 0 | C27: 0 | D27: 0 | E27: 0 | F27: 0 | G27: 0 | H27: 0 | I27: 4561.88 | J27: 2108.34 | K27: 6670.22 | M27: MGNT - Patients / Surgery management | N27: 29636.09 | O27: 0 | P27: 40445.36 | Q27: 0 | R27: 0 | S27: 72033.16 | T27: 106375.98 | U27: 101569.79 | V27: 105538.29 | W27: 455598.67
A28: Medical Waste | B28: 0 | C28: 1122.52 | D28: 10182.12 | E28: 7514.72 | F28: 812.49 | G28: 633.66 | H28: 807.32 | I28: 6566.54 | J28: 1980.9 | K28: 29620.27 | M28: MGNT - Practice Management | N28: 29636.09 | O28: 0 | P28: 67030.91 | Q28: 0 | R28: 0 | S28: 108049.73 | T28: 159563.97 | U28: 152354.69 | V28: 158307.43 | W28: 674942.82
A29: Minor Assets | B29: 3477.39 | C29: 0 | D29: 0 | E29: 0 | F29: 0 | G29: 0 | H29: 0 | I29: 0 | J29: 10004 | K29: 13481.39 | M29: MGNT - Rental | N29: 29636.09 | O29: 0 | P29: 21373.81 | Q29: 0 | R29: 0 | S29: 36016.58 | T29: 53187.99 | U29: 50784.9 | V29: 52769.14 | W29: 243768.51
A30: Motor Vehicle Expenses & Fuel | B30: 0 | C30: 1150 | D30: 0 | E30: 0 | F30: 0 | G30: 0 | H30: 0 | I30: 0 | J30: 0 | K30: 1150 | M30: Minor Assets | N30: 5925 | O30: 10777.58 | P30: 0 | Q30: 0 | R30: 0 | S30: 0 | T30: 0 | U30: 11755.08 | V30: 6486.95 | W30: 34944.61
A31: Payroll : Director Nett | B31: 31983.55 | C31: 31983.55 | D31: 31983.55 | E31: 31983.55 | F31: 31983.54 | G31: 31983.55 | H31: 31983.55 | I31: 31983.54 | J31: 31983.55 | K31: 287851.93 | M31: Motor Vehicle Expense - Fuel | N31: 2547.92 | O31: 7839.21 | P31: 9886.4 | Q31: 3224.24 | R31: 9912.61 | S31: 4707.2 | T31: 6822.75 | U31: 6272.3 | V31: 11317.99 | W31: 62530.62
... A47: Utilities | B47: 1739.13 | C47: 13043.49 | D47: 5000 | E47: 5000 | F47: 4000 | G47: 2100 | H47: 0 | I47: 0 | J47: 0 | K47: 30882.62 | M47: TOT - Data capture | N47: 0 | O47: 0 | P47: 18079.22 | Q47: 17489.28 | R47: 21074.14 | S47: 19208.84 | T47: 28366.93 | U47: 27085.28 | V47: 28143.54 | W47: 159447.23
A48: Total Operating Expenses | B48: =SUM(B20:B47) -> 1264229.6 | C48: =SUM(C20:C47) -> 1445047.7 | D48: =SUM(D20:D47) -> 1457359.9 | E48: =SUM(E20:E47) -> 1445114.6 | F48: =SUM(F20:F47) -> 1615150.2 | G48: =SUM(G20:G47) -> 1447641.3 | H48: =SUM(H20:H47) -> 1423132.5 | I48: =SUM(I20:I47) -> 1364574.2 | ... K48: =SUM(K20:K47) -> 12798932 | M48: TOT - Medical patients records | N48: 0 | O48: 0 | P48: 12052.81 | Q48: 11659.52 | R48: 14049.43 | S48: 12805.89 | T48: 18911.29 | U48: 18056.85 | V48: 18762.36 | W48: 106298.15
M49: Travel - International | N49: 206514.51 | O49: 145637.63 | P49: 157986.56 | Q49: 153591.64 | R49: 121106.47 | S49: 135958.68 | T49: 66424.61 | U49: 42561.52 | V49: 0 | W49: 1029781.6
A50: Net Profit | B50: =((B17 + 0) - B48) -> 396162.2 | C50: =((C17 + 0) - C48) -> 468694.21 | D50: =((D17 + 0) - D48) -> 498299.32 | E50: =((E17 + 0) - E48) -> 1002924.1 | F50: =((F17 + 0) - F48) -> 97181.28 | G50: =((G17 + 0) - G48) -> 4693.72 | H50: =((H17 + 0) - H48) -> 671261.04 | I50: =((I17 + 0) - I48) -> 223174.74 | ... K50: =((K17 + 0) - K48) -> 2893998.6 | M50: Travel - National | N50: 13580.02 | O50: 54920.9 | P50: 33644.18 | Q50: 7949.6 | R50: 6940.06 | S50: 5126.13 | T50: 7506.09 | U50: 6635.69 | V50: 1545.22 | W50: 137847.89
M51: Utilities | N51: 4347.83 | O51: 0 | P51: 4347.83 | Q51: 0 | R51: 5217.39 | S51: 0 | T51: 0 | U51: 0 | V51: 0 | W51: 13913.05
M52: Total Operating Expenses | N52: =SUM(N19:N51) -> 1956108.5 | O52: =SUM(O19:O51) -> 2045880.4 | P52: =SUM(P19:P51) -> 2141548.1 | Q52: =SUM(Q19:Q51) -> 1942706.8 | R52: =SUM(R19:R51) -> 1880238.8 | S52: =SUM(S19:S51) -> 2029121.2 | T52: =SUM(T19:T51) -> 2026302 | U52: =SUM(U19:U51) -> 2081013.1 | ... W52: =SUM(W19:W51) -> 18114019
M54: Net Profit | N54: =((N16 + 0) - N52) -> -1281137.5 | O54: =((O16 + 0) - O52) -> -919989.47 | P54: =((P16 + 0) - P52) -> -1554412 | Q54: =((Q16 + 0) - Q52) -> -1488093.9 | R54: =((R16 + 0) - R52) -> -894196.82 | S54: =((S16 + 0) - S52) -> -1382943.9 | T54: =((T16 + 0) - T52) -> -997440.71 | U54: =((U16 + 0) - U52) -> -697155.19 | ... W54: =((W16 + 0) - W52) -> -9028541.6
Q56: =W52+K48-1125000 -> 29787951

Sheet Combined
A1: Profit and Loss Combined | E1: Within 25% of Budget | H1: Over 25% of Budget | K1: Under 25% of Budget
A2: Sanctura SA
A3: For the month ended 30 November 2025
B4: Saint Raphael | C4: JLI | D4: Intracompany | E4: Total Comb | F4: Reforecast | G4: % Variance | H4: R Variance | J4: Year to Date | K4: Reforecast YTD | L4: % Variance | M4: R Variance
A5: Account | B5: 45962 | C5: 45962 | D5: 45962 | E5: 45962 | F5: 45962 | G5: 45962 | H5: 45962 | J5: 45962 | K5: 45962 | L5: 45962 | M5: 45962
A7: Trading Income
A8: Interest Income | B8: ='SA P & L'!B8 -> 297.19 | C8: ='SA P & L'!N8 -> 749.63 | E8: =SUM(B8:D8) -> 1046.82 | J8: ='SA P & L'!W8+'SA P & L'!K8 -> 19921
A9: Sales | B9: ='SA P & L'!B10 -> 1571884.9 | C9: ='SA P & L'!N9 -> 1092297.5 | D9: =-1571885 -> -1571885 | E9: =SUM(B9:D9) -> 1092297.4 | F9: ='SA V2'!S273 -> 2397090.4 | J9: ='SA P & L'!W9 -> 16080375 | K9: =SUM('SA V2'!K273:S273) -> 19245201
A10: Total Trading Income | B10: =SUM(B8:B9) -> 1572182.1 | C10: =SUM(C8:C9) -> 1093047.1 | D10: =SUM(D8:D9) -> -1571885 | E10: =SUM(E8:E9) -> 1093344.2 | F10: =SUM(F8:F9) -> 2397090.4 | G10: =(E10-F10)/F10*100 -> -54.388694 | H10: =E10-F10 -> -1303746.1 | J10: =SUM(J8:J9) -> 16100296 | K10: =SUM(K9:K9) -> 19245201 | L10: =(J10-K10)/K10*100 -> -16.34124 | M10: =J10-K10 -> -3144904.5
A12: Cost of Sales
A13: Cost of Goods Sold | B13: ='SA P & L'!B14 -> 138381.17 | C13: ='SA P & L'!N13 -> 418076.09 | D13: =-231635 -> -231635 | E13: =SUM(B13:D13) -> 324822.26 | F13: =-SUM('SA V2'!S276:S287) -> 796080.52 | J13: ='SA P & L'!K14+'SA P & L'!W13-N13 -> 5898711 | K13: =-SUM('SA V2'!K276:S287) -> 6923922.3 | N13: =2447398.19+279069+231634 -> 2958101.2
A14: Total Cost of Sales | B14: =B13 -> 138381.17 | C14: =C13 -> 418076.09 | D14: =D13 -> -231635 | E14: =E13 -> 324822.26 | F14: =F13 -> 796080.52 | G14: =(E14-F14)/F14*100 -> -59.197311 | H14: =E14-F14 -> -471258.26 | J14: =J13 -> 5898711 | K14: =K13 -> 6923922.3 | L14: =(J14-K14)/K14*100 -> -14.8068 | M14: =J14-K14 -> -1025211.3
A16: Gross Profit | B16: =(B10 - B14) -> 1433800.9 | C16: =(C10 - C14) -> 674971.05 | E16: =(E10 - E14) -> 768521.97 | F16: =(F10 - F14) -> 1601009.9 | G16: =(E16-F16)/F16*100 -> -51.997674 | H16: =E16-F16 -> -832487.89 | J16: =(J10 - J14) -> 10201585 | K16: =(K10 - K14) -> 12321279 | L16: =(J16-K16)/K16*100 -> -17.203517 | M16: =J16-K16 -> -2119693.2
A18: Operating Expenses
A19: Bank Fees | B19: ='SA P & L'!B21 -> 1422.69 | C19: ='SA P & L'!N20 -> 24925.86 | E19: =SUM(B19:D19) -> 26348.55 | F19: ='SA V2'!S205 -> 28980.143 | G19: =(E19-F19)/F19*100 -> -9.0806759 | H19: =E19-F19 -> -2631.5929 | J19: ='SA P & L'!K21+'SA P & L'!W20 -> 246408.18 | K19: =SUM('SA V2'!K205:S205) -> 270978.57 | L19: =(J19-K19)/K19*100 -> -9.0672821 | M19: =J19-K19 -> -24570.391
A20: Casual Wages | B20: ='SA P & L'!B22 -> 0 | C20: 0 | E20: =SUM(B20:D20) -> 0 | F20: ='SA V2'!S206 -> 5600 | G20: =(E20-F20)/F20*100 -> -100 | H20: =E20-F20 -> -5600 | J20: ='SA P & L'!K22 -> 44806.54 | K20: =SUM('SA V2'!K206:S206) -> 24400 | L20: =(J20-K20)/K20*100 -> 83.633361 | M20: =J20-K20 -> 20406.54
A21: Consulting, Accounting, Legal & Administrative Fees | B21: ='SA P & L'!B24 -> 22945 | C21: ='SA P & L'!N22-125000 -> 0 | E21: =SUM(B21:D21) -> 22945 | F21: ='SA V2'!S207 -> 24076.857 | G21: =(E21-F21)/F21*100 -> -4.701017 | H21: =E21-F21 -> -1131.8571 | J21: ='SA P & L'!K24+'SA P & L'!K27+'SA P & L'!W22-N43 -> 184755.27 | K21: =SUM('SA V2'!K207:S207) -> 200297.43 | L21: =(J21-K21)/K21*100 -> -7.7595397 | M21: =J21-K21 -> -15542.159
A22: Entertainment & Staff Welfare | B22: ='SA P & L'!B42 -> 15450 | C22: ='SA P & L'!N43 -> 6035.09 | E22: =SUM(B22:D22) -> 21485.09 | F22: ='SA V2'!S209 -> 13439.857 | G22: =(E22-F22)/F22*100 -> 59.861 | H22: =E22-F22 -> 8045.2329 | J22: ='SA P & L'!K42+'SA P & L'!W43 -> 115197.32 | K22: =SUM('SA V2'!K209:S209) -> 110181.43 | L22: =(J22-K22)/K22*100 -> 4.5523928 | M22: =J22-K22 -> 5015.8914
A23: Freight & Courier, Printing & Stationary | B23: ='SA P & L'!B37+'SA P & L'!B36 -> 3800.9 | C23: ='SA P & L'!N36+'SA P & L'!N37 -> 3639.31 | E23: =SUM(B23:D23) -> 7440.21 | F23: ='SA V2'!S210 -> 9210.4286 | G23: =(E23-F23)/F23*100 -> -19.21972 | H23: =E23-F23 -> -1770.2186 | J23: ='SA P & L'!K36+'SA P & L'!K37+'SA P & L'!W36+'SA P & L'!W37 -> 78596.19 | K23: =SUM('SA V2'!K210:S210) -> 93895.714 | L23: =(J23-K23)/K23*100 -> -16.294167 | M23: =J23-K23 -> -15299.524
A24: Insurance | B24: =0 -> 0 | C24: ='SA P & L'!N24 -> 34962.81 | E24: =SUM(B24:D24) -> 34962.81 | F24: ='SA V2'!S211 -> 60480 | G24: =(E24-F24)/F24*100 -> -42.191121 | H24: =E24-F24 -> -25517.19 | J24: ='SA P & L'!W24 -> 249544.69 | K24: =SUM('SA V2'!K211:S211) -> 362132 | L24: =(J24-K24)/K24*100 -> -31.09013 | M24: =J24-K24 -> -112587.31
A25: Minor assets | B25: ='SA P & L'!B29 -> 3477.39 | C25: ='SA P & L'!N30 -> 5925 | E25: =SUM(B25:D25) -> 9402.39 | F25: ='SA V2'!S212 -> 6975 | G25: =(E25-F25)/F25*100 -> 34.80129 | H25: =E25-F25 -> 2427.39 | J25: ='SA P & L'!W30+'SA P & L'!K29 -> 48426 | K25: =SUM('SA V2'!K212:S212) -> 57874 | L25: =(J25-K25)/K25*100 -> -16.32512 | M25: =J25-K25 -> -9448
A26: Motor Vehicle Expenses and Fuel | B26: 0 | C26: ='SA P & L'!N31+'SA P & L'!N32 -> 3234 | E26: =SUM(B26:D26) -> 3234 | F26: ='SA V2'!S213 -> 25845.571 | G26: =(E26-F26)/F26*100 -> -87.487218 | H26: =E26-F26 -> -22611.571 | J26: ='SA P & L'!W31+'SA P & L'!W32+'SA P & L'!K30 -> 116186.89 | K26: =SUM('SA V2'!K213:S213) -> 190107.29 | L26: =(J26-K26)/K26*100 -> -38.883515 | M26: =J26-K26 -> -73920.396
A27: Office, Cleaning, Medical Waste, Security | B27: ='SA P & L'!B23+'SA P & L'!B26+'SA P & L'!B28 -> 2550.22 | C27: ='SA P & L'!N40+'SA P & L'!N21 -> 19448.95 | E27: =SUM(B27:D27) -> 21999.17 | F27: ='SA V2'!S214 -> 28257.286 | G27: =(E27-F27)/F27*100 -> -22.14691 | H27: =E27-F27 -> -6258.1157 | J27: ='SA P & L'!W21+'SA P & L'!W40+'SA P & L'!K28+'SA P & L'!K23+'SA P & L'!K26 -> 334696.66 | K27: =SUM('SA V2'!K214:S214) -> 260677.14 | L27: =(J27-K27)/K27*100 -> 28.395093 | M27: =J27-K27 -> 74019.517
A28: Rent and Utilities | B28: ='SA P & L'!B39+'SA P & L'!B47 -> 81413.16 | C28: ='SA P & L'!N51 -> 4347.83 | E28: =SUM(B28:D28) -> 85760.99 | F28: ='SA V2'!S215 -> 98609.143 | G28: =(E28-F28)/F28*100 -> -13.029373 | H28: =E28-F28 -> -12848.153 | J28: ='SA P & L'!W51+'SA P & L'!K47+'SA P & L'!K39 -> 859727.07 | K28: =SUM('SA V2'!K215:S215) -> 885734.57 | L28: =(J28-K28)/K28*100 -> -2.9362636 | M28: =J28-K28 -> -26007.501
A29: Repairs and Maintenance | B29: ='SA P & L'!B40 -> 21556.05 | C29: ='SA P & L'!N38 -> 485.22 | E29: =SUM(B29:D29) -> 22041.27 | F29: ='SA V2'!S216 -> 5674.7143 | G29: =(E29-F29)/F29*100 -> 288.41198 | H29: =E29-F29 -> 16366.556 | J29: ='SA P & L'!K40+'SA P & L'!W38 -> 250318.15 | K29: =SUM('SA V2'!K216:S216) -> 43802.857 | L29: =(J29-K29)/K29*100 -> 471.46535 | M29: =J29-K29 -> 206515.29
A30: Staff Clothing | B30: =0 -> 0 | C30: ='SA P & L'!N41 -> 0 | E30: =SUM(B30:D30) -> 0 | F30: ='SA V2'!S217 -> 2120.2857 | G30: =(E30-F30)/F30*100 -> -100 | H30: =E30-F30 -> -2120.2857 | J30: ='SA P & L'!W41 -> 25682.6 | K30: =SUM('SA V2'!K217:S217) -> 22829.143 | L30: =(J30-K30)/K30*100 -> 12.499187 | M30: =J30-K30 -> 2853.4571
A31: Subscriptions | B31: ='SA P & L'!B43 -> 30262.2 | C31: ='SA P & L'!N44 -> 3594.09 | E31: =SUM(B31:D31) -> 33856.29 | F31: ='SA V2'!S218 -> 22047.714 | G31: =(E31-F31)/F31*100 -> 53.559183 | H31: =E31-F31 -> 11808.576 | J31: ='SA P & L'!W44+'SA P & L'!K43 -> 261540.75 | K31: =SUM('SA V2'!K218:S218) -> 211792.86 | L31: =(J31-K31)/K31*100 -> 23.488938 | M31: =J31-K31 -> 49747.893
A32: Telephone & Internet | B32: =0 -> 0 | C32: ='SA P & L'!N45 -> 8642.3 | E32: =SUM(B32:D32) -> 8642.3 | F32: ='SA V2'!S219 -> 5219.8571 | G32: =(E32-F32)/F32*100 -> 65.565834 | H32: =E32-F32 -> 3422.4429 | J32: ='SA P & L'!W45 -> 52826.5 | K32: =SUM('SA V2'!K219:S219) -> 46734.429 | L32: =(J32-K32)/K32*100 -> 13.035511 | M32: =J32-K32 -> 6092.0714
A33: Training and conferences | B33: ='SA P & L'!B41 -> -20052.18 | C33: ='SA P & L'!N42 -> 0 | E33: =SUM(B33:D33) -> -20052.18 | F33: ='SA V2'!S220 -> 10624.286 | G33: =(E33-F33)/F33*100 -> -288.73909 | H33: =E33-F33 -> -30676.466 | J33: ='SA P & L'!K41+'SA P & L'!W42 -> 75312.82 | K33: =SUM('SA V2'!K220:S220) -> 105519.14 | L33: =(J33-K33)/K33*100 -> -28.626391 | M33: =J33-K33 -> -30206.323
A34: Travel - International | B34: ='SA P & L'!B44 -> 72397.39 | C34: ='SA P & L'!N49 -> 206514.51 | E34: =SUM(B34:D34) -> 278911.9 | F34: ='SA V2'!S221 -> 161387 | G34: =(E34-F34)/F34*100 -> 72.821789 | H34: =E34-F34 -> 117524.9 | J34: ='SA P & L'!K44+'SA P & L'!W49 -> 1923653.5 | K34: =SUM('SA V2'!K221:S221) -> 1691737 | L34: =(J34-K34)/K34*100 -> 13.708782 | M34: =J34-K34 -> 231916.54
A35: Travel - National | B35: ='SA P & L'!B45 -> 0 | C35: ='SA P & L'!N50 -> 13580.02 | E35: =SUM(B35:D35) -> 13580.02 | F35: ='SA V2'!S222 -> 5347.1429 | G35: =(E35-F35)/F35*100 -> 153.96778 | H35: =E35-F35 -> 8232.8771 | J35: ='SA P & L'!W50+'SA P & L'!K45 -> 146911.31 | K35: =SUM('SA V2'!K222:S222) -> 49378.571 | L35: =(J35-K35)/K35*100 -> 197.52037 | M35: =J35-K35 -> 97532.739
A36: Contingency | B36: 0 | C36: 0 | E36: =SUM(B36:D36) -> 0 | F36: ='SA V2'!S223 -> 35000 | G36: =(E36-F36)/F36*100 -> -100 | H36: =E36-F36 -> -35000 | J36: 0 | K36: =SUM('SA V2'!K223:S223) -> 315000 | L36: =(J36-K36)/K36*100 -> -100 | M36: =J36-K36 -> -315000
A37: Advertising | B37: ='SA P & L'!B20 -> 53660.37 | C37: ='SA P & L'!N19 -> 125000 | D37: =-125000 -> -125000 | E37: =SUM(B37:D37) -> 53660.37 | F37: ='SA V2'!S204 -> 125000 | G37: =(E37-F37)/F37*100 -> -57.071704 | H37: =E37-F37 -> -71339.63 | J37: ='SA P & L'!K20 -> 753629.54 | K37: =SUM('SA V2'!K204:S204) -> 940243 | L37: =(J37-K37)/K37*100 -> -19.847365 | M37: =J37-K37 -> -186613.46
A38: Practice Management | B38: 0 | C38: ='SA P & L'!N39 -> 1215250 | D38: =-1215250 -> -1215250 | E38: =SUM(B38:D38) -> 0 | H38: =E38-F38 -> 0
A39: Unrealised Currency Gains / Losses | B39: ='SA P & L'!B38+'SA P & L'!B46 -> 8790.78 | E39: =SUM(B39:D39) -> 8790.78 | J39: ='SA P & L'!K38+'SA P & L'!K46 -> -13774.97
E40: =SUM(B40:D40) -> 0
A41: Staff Costs: | E41: =SUM(B41:D41) -> 0
A42: Director's Emoluments | B42: ='SA P & L'!B31+'SA P & L'!B32 -> 40000 | C42: =SUM('SA P & L'!N46:N48)+SUM('SA P & L'!N25:N29) -> 128544.36 | E42: =SUM(B42:D42) -> 168544.36 | F42: ='SA V2'!S181 -> 250000 | G42: =(E42-F42)/F42*100 -> -32.582256 | H42: =E42-F42 -> -81455.64 | J42: ='SA P & L'!K31+'SA P & L'!K32+SUM('SA P & L'!W46:W48)+SUM('SA P & L'!W25:W29) -> 2379229.1 | K42: =-(SUM('SA V2'!K296:R296)) -> 2000000 | L42: =(J42-K42)/K42*100 -> 18.961457 | M42: =J42-K42 -> 379229.15
A43: Wages and Salaries | B43: ='SA P & L'!B33+'SA P & L'!B34+'SA P & L'!B35 -> 648871.26 | C43: 125000 | E43: =SUM(B43:D43) -> 773871.26 | F43: =-('SA V2'!S298-'SA V2'!S296) -> 890746.39 | G43: =(E43-F43)/F43*100 -> -13.121033 | H43: =E43-F43 -> -116875.13 | J43: =SUM('SA P & L'!K33:K35)+SUM('SA P & L'!W33:W35)+N43 -> 7536016.5 | K43: =(-SUM('SA V2'!K298:S298)-Combined!K42) -> 7935628.9 | L43: =(J43-K43)/K43*100 -> -5.0356747 | M43: =J43-K43 -> -399612.46 | N43: =290384.62+125000+125000 -> 540384.62
E44: =SUM(B44:D44) -> 0
...

Sheet SA V2
C1: GBP | D1: =D3/$D$2 -> -359792.81 | E1: =E3/$D$2 -> 170927.79 | F1: =F3/$D$2 -> 345477.59 | G1: =G3/$D$2 -> 937456.63
C2: GBP:ZAR | D2: =22.6-(22.6*0.4%) -> 22.5096 | I2: =YEAR(I4) -> 2025 | J2: =YEAR(J4) -> 2025 | K2: =YEAR(K4) -> 2025 | L2: =YEAR(L4) -> 2025 | M2: =YEAR(M4) -> 2025 | N2: =YEAR(N4) -> 2025 | O2: =YEAR(O4) -> 2025 | P2: =YEAR(P4) -> 2025 | ... BD2: =YEAR(BD4) -> 2028
C3: Rands | D3: =D$354 -> -8098792.2 | E3: =E$354 -> 3847516.1 | F3: =F$354 -> 7776562.4 | G3: =G$354 -> 21101774 | I3: Actual | J3: Actual | K3: Actual | L3: Actual | M3: Actual | N3: Actual | O3: Actual | P3: Forecast
D4: 2025 | E4: 2026 | F4: 2027 | G4: 2028 | I4: 45688 | J4: =EOMONTH(I4,1) -> 45716 | K4: =EOMONTH(J4,1) -> 45747 | L4: =EOMONTH(K4,1) -> 45777 | M4: =EOMONTH(L4,1) -> 45808 | N4: =EOMONTH(M4,1) -> 45838 | O4: =EOMONTH(N4,1) -> 45869 | P4: =EOMONTH(O4,1) -> 45900 | Q4: =EOMONTH(P4,1) -> 45930 | ... BD4: =EOMONTH(BC4,1) -> 47118
B5: ASSUMPTIONS
B7: Revenue Assumptions
C9: Treatment commencement | D9: =I4 -> 45688 | I9: =IF(I4>=$D$9,1,0) -> 1 | J9: =IF(J4>=$D$9,1,0) -> 1 | K9: =IF(K4>=$D$9,1,0) -> 1 | L9: =IF(L4>=$D$9,1,0) -> 1 | M9: =IF(M4>=$D$9,1,0) -> 1 | N9: =IF(N4>=$D$9,1,0) -> 1 | O9: =IF(O4>=$D$9,1,0) -> 1 | P9: =IF(P4>=$D$9,1,0) -> 1 | ... BD9: =IF(BD4>=$D$9,1,0) -> 1
C12: IV Treatments | D12: Min | E12: Max | F12: Growth Rate
C13: IV Number of Treatments | D13: 25 | E13: 200 | F13: 0.01 | I13: 47 | J13: 43 | K13: 63 | L13: 54 | M13: 39 | N13: 35 | O13: 75 | P13: =MIN(MAX($D13,O13)*(1+$F13)*P$9,$E13) -> 75.75 | Q13: =MIN(MAX($D13,P13)*(1+$F13)*Q$9,$E13) -> 76.5075 | R13: =MIN(MAX($D13,Q13)*(1+$F13)*R$9,$E13) -> 77.272575 | S13: =MIN(MAX($D13,R13)*(1+$F13)*S$9,$E13) -> 78.045301 | T13: =MIN(MAX($D13,S13)*(1+$F13)*T$9,$E13) -> 78.825754 | U13: =MIN(MAX($D13,T13)*(1+$F13)*U$9,$E13) -> 79.614011 | V13: =MIN(MAX($D13,U13)*(1+$F13)*V$9,$E13) -> 80.410151 | W13: =MIN(MAX($D13,V13)*(1+$F13)*W$9,$E13) -> 81.214253 | ... BD13: =MIN(MAX($D13,BC13)*(1+$F13)*BD$9,$E13) -> 112.78143
C14: Average Revenue / Treatment | D14: 3500 | E14: 4500 | F14: 0 | I14: 3320 | J14: 4101 | K14: 3165 | L14: 4502 | M14: 4166 | N14: 3777 | O14: 3143 | P14: =MIN(MAX($D14,O14)*(1+$F14)*P$9,$E14) -> 3500 | Q14: =MIN(MAX($D14,P14)*(1+$F14)*Q$9,$E14) -> 3500 | R14: =MIN(MAX($D14,Q14)*(1+$F14)*R$9,$E14) -> 3500 | S14: =MIN(MAX($D14,R14)*(1+$F14)*S$9,$E14) -> 3500 | T14: =MIN(MAX($D14,S14)*(1+$F14)*T$9,$E14) -> 3500 | U14: =MIN(MAX($D14,T14)*(1+$F14)*U$9,$E14) -> 3500 | V14: =MIN(MAX($D14,U14)*(1+$F14)*V$9,$E14) -> 3500 | W14: =MIN(MAX($D14,V14)*(1+$F14)*W$9,$E14) -> 3500 | ... BD14: =MIN(MAX($D14,BC14)*(1+$F14)*BD$9,$E14) -> 3500
C15: IV Treatment Revenue | I15: =I13*I14 -> 156040 | J15: =J13*J14 -> 176343 | K15: =K13*K14 -> 199395 | L15: =L13*L14 -> 243108 | M15: =M13*M14 -> 162474 | N15: =N13*N14 -> 132195 | O15: =O13*O14 -> 235725 | P15: =P13*P14 -> 265125 | ... BD15: =BD13*BD14 -> 394735
C17: IV COS | D17: =-(D14*0.3) -> -1050 | I17: =-I15*0.3 -> -46812 | J17: =-J15*0.3 -> -52902.9 | K17: =-K15*0.3 -> -59818.5 | L17: =-L15*0.3 -> -72932.4 | M17: =-M15*0.3 -> -48742.2 | N17: =-N15*0.3 -> -39658.5 | O17: =-O15*0.3 -> -70717.5 | P17: =P13*$D17 -> -79537.5 | Q17: =Q13*$D17 -> -80332.875 | R17: =R13*$D17 -> -81136.204 | S17: =S13*$D17 -> -81947.566 | T17: =T13*$D17 -> -82767.041 | U17: =U13*$D17 -> -83594.712 | V17: =V13*$D17 -> -84430.659 | W17: =W13*$D17 -> -85274.966 | ... BD17: =BD13*$D17 -> -118420.5
C19: IV Curcumin 150mg Treatments | D19: Min | E19: Max | F19: Growth Rate
C20: IV Curcumin Number of Treatments | D20: 25 | E20: 45 | F20: 0.01 | I20: 29 | J20: =MIN(MAX($D20,I20)*(1+$F20)*J$9,$E20) -> 29.29 | K20: 32 | L20: 39 | M20: 15 | N20: 7 | O20: 28 | P20: =MIN(MAX($D20,O20)*(1+$F20)*P$9,$E20) -> 28.28 | Q20: =MIN(MAX($D20,P20)*(1+$F20)*Q$9,$E20) -> 28.5628 | R20: =MIN(MAX($D20,Q20)*(1+$F20)*R$9,$E20) -> 28.848428 | S20: =MIN(MAX($D20,R20)*(1+$F20)*S$9,$E20) -> 29.136912 | T20: =MIN(MAX($D20,S20)*(1+$F20)*T$9,$E20) -> 29.428281 | U20: =MIN(MAX($D20,T20)*(1+$F20)*U$9,$E20) -> 29.722564 | V20: =MIN(MAX($D20,U20)*(1+$F20)*V$9,$E20) -> 30.01979 | W20: =MIN(MAX($D20,V20)*(1+$F20)*W$9,$E20) -> 30.319988 | ... BD20: =MIN(MAX($D20,BC20)*(1+$F20)*BD$9,$E20) -> 42.105066
C21: Average Revenue / Treatment | D21: 6500 | E21: 7500 | F21: 0.02 | I21: 5016 | J21: 5379 | K21: 5898 | L21: 6045 | M21: 5762 | N21: 7000 | O21: 5026 | P21: =MIN(MAX($D21,O21)*(1+$F21)*P$9,$E21) -> 6630 | Q21: =MIN(MAX($D21,P21)*(1+$F21)*Q$9,$E21) -> 6762.6 | R21: =MIN(MAX($D21,Q21)*(1+$F21)*R$9,$E21) -> 6897.852 | S21: =MIN(MAX($D21,R21)*(1+$F21)*S$9,$E21) -> 7035.809 | T21: =MIN(MAX($D21,S21)*(1+$F21)*T$9,$E21) -> 7176.5252 | U21: =MIN(MAX($D21,T21)*(1+$F21)*U$9,$E21) -> 7320.0557 | V21: =MIN(MAX($D21,U21)*(1+$F21)*V$9,$E21) -> 7466.4568 | W21: =MIN(MAX($D21,V21)*(1+$F21)*W$9,$E21) -> 7500 | ... BD21: =MIN(MAX($D21,BC21)*(1+$F21)*BD$9,$E21) -> 7500
C22: IV CurcuminTreatment Revenue | I22: =I20*I21 -> 145464 | J22: =J20*J21 -> 157550.91 | K22: =K20*K21 -> 188736 | L22: =L20*L21 -> 235755 | M22: =M20*M21 -> 86430 | N22: =N20*N21 -> 49000 | O22: =O20*O21 -> 140728 | P22: =P20*P21 -> 187496.4 | ... BD22: =BD20*BD21 -> 315788
C24: IV Curcumin COS | D24: =-(D21*0.3) -> -1950 | I24: =-I22*0.3 -> -43639.2 | J24: =-J22*0.3 -> -47265.273 | K24: =-K22*0.3 -> -56620.8 | L24: =-L22*0.3 -> -70726.5 | M24: =-M22*0.3 -> -25929 | N24: =-N22*0.3 -> -14700 | O24: =-O22*0.3 -> -42218.4 | P24: =P20*$D24 -> -55146 | Q24: =Q20*$D24 -> -55697.46 | R24: =R20*$D24 -> -56254.435 | S24: =S20*$D24 -> -56816.979 | T24: =T20*$D24 -> -57385.149 | U24: =U20*$D24 -> -57959 | V24: =V20*$D24 -> -58538.59 | W24: =W20*$D24 -> -59123.976 | ... BD24: =BD20*$D24 -> -82104.879
C26: Laser Treatments | D26: Min | E26: Max | F26: Growth Rate
C27: Laser Number of Treatments | D27: 15 | E27: 350 | F27: 0.02 | I27: 48 | J27: 30 | K27: 50 | L27: 40 | M27: 10 | N27: 0 | O27: 17 | P27: =MIN(MAX($D27,O27)*(1+$F27)*P$9,$E27) -> 17.34 | Q27: =MIN(MAX($D27,P27)*(1+$F27)*Q$9,$E27) -> 17.6868 | R27: =MIN(MAX($D27,Q27)*(1+$F27)*R$9,$E27) -> 18.040536 | S27: =MIN(MAX($D27,R27)*(1+$F27)*S$9,$E27) -> 18.401347 | T27: =MIN(MAX($D27,S27)*(1+$F27)*T$9,$E27) -> 18.769374 | U27: =MIN(MAX($D27,T27)*(1+$F27)*U$9,$E27) -> 19.144761 | V27: =MIN(MAX($D27,U27)*(1+$F27)*V$9,$E27) -> 19.527656 | W27: =MIN(MAX($D27,V27)*(1+$F27)*W$9,$E27) -> 19.918209 | ... BD27: =MIN(MAX($D27,BC27)*(1+$F27)*BD$9,$E27) -> 38.287408
C28: Average Revenue / Treatment | D28: =SUM(I28:O28)/7 -> 654.14286 | E28: 2775 | F28: 0 | I28: 750 | J28: 574 | K28: 565 | L28: 691 | M28: 717 | N28: 750 | O28: 532 | P28: =MIN(MAX($D28,O28)*(1+$F28)*P$9,$E28) -> 654.14286 | Q28: =MIN(MAX($D28,P28)*(1+$F28)*Q$9,$E28) -> 654.14286 | R28: =MIN(MAX($D28,Q28)*(1+$F28)*R$9,$E28) -> 654.14286 | S28: =MIN(MAX($D28,R28)*(1+$F28)*S$9,$E28) -> 654.14286 | T28: =MIN(MAX($D28,S28)*(1+$F28)*T$9,$E28) -> 654.14286 | U28: =MIN(MAX($D28,T28)*(1+$F28)*U$9,$E28) -> 654.14286 | V28: =MIN(MAX($D28,U28)*(1+$F28)*V$9,$E28) -> 654.14286 | W28: =MIN(MAX($D28,V28)*(1+$F28)*W$9,$E28) -> 654.14286 | ... BD28: =MIN(MAX($D28,BC28)*(1+$F28)*BD$9,$E28) -> 654.14286
C29: Laser Treatment Revenue | I29: =I27*I28 -> 36000 | J29: =J27*J28 -> 17220 | K29: =K27*K28 -> 28250 | L29: =L27*L28 -> 27640 | M29: =M27*M28 -> 7170 | N29: =N27*N28 -> 0 | O29: =O27*O28 -> 9044 | P29: =P27*P28 -> 11342.837 | ... BD29: =BD27*BD28 -> 25045.434
C31: Hyperthermia (mEHT) 1 | D31: Min | E31: Max | F31: Growth Rate
C32: mEHT Number of Sessions | D32: 80 | E32: 208 | F32: 0.05 | I32: 147 | J32: 127.5 | K32: 166 | L32: 132 | M32: 79.5 | N32: 102 | O32: 100.5 | P32: =MIN(MAX($D32,O32)*(1+$F32)*P$9,$E32) -> 105.525 | Q32: =MIN(MAX($D32,P32)*(1+$F32)*Q$9,$E32) -> 110.80125 | R32: =MIN(MAX($D32,Q32)*(1+$F32)*R$9,$E32) -> 116.34131 | S32: =MIN(MAX($D32,R32)*(1+$F32)*S$9,$E32) -> 122.15838 | T32: =MIN(MAX($D32,S32)*(1+$F32)*T$9,$E32) -> 128.2663 | U32: =MIN(MAX($D32,T32)*(1+$F32)*U$9,$E32) -> 134.67961 | V32: =MIN(MAX($D32,U32)*(1+$F32)*V$9,$E32) -> 141.41359 | W32: =MIN(MAX($D32,V32)*(1+$F32)*W$9,$E32) -> 148.48427 | ... BD32: =MIN(MAX($D32,BC32)*(1+$F32)*BD$9,$E32) -> 208
C33: Average Revenue / Session | D33: 3091 | E33: 3555 | F33: 0 | I33: =3555/1.15 -> 3091.3043 | J33: 3091 | K33: =MIN(MAX($D33,J33)*(1+$F33)*K$9,$E33) -> 3091 | L33: =MIN(MAX($D33,K33)*(1+$F33)*L$9,$E33) -> 3091 | M33: =MIN(MAX($D33,L33)*(1+$F33)*M$9,$E33) -> 3091 | N33: =MIN(MAX($D33,M33)*(1+$F33)*N$9,$E33) -> 3091 | O33: =MIN(MAX($D33,N33)*(1+$F33)*O$9,$E33) -> 3091 | P33: =MIN(MAX($D33,O33)*(1+$F33)*P$9,$E33) -> 3091 | Q33: =MIN(MAX($D33,P33)*(1+$F33)*Q$9,$E33) -> 3091 | R33: =MIN(MAX($D33,Q33)*(1+$F33)*R$9,$E33) -> 3091 | ... BD33: =MIN(MAX($D33,BC33)*(1+$F33)*BD$9,$E33) -> 3091
C34: Hyperthermia Session Revenue | I34: =I32*I33 -> 454421.74 | J34: =J32*J33 -> 394102.5 | K34: =K32*K33 -> 513106 | L34: =L32*L33 -> 408012 | M34: =M32*M33 -> 245734.5 | N34: =N32*N33 -> 315282 | O34: =O32*O33 -> 310645.5 | P34: =P32*P33 -> 326177.78 | ... BD34: =BD32*BD33 -> 642928
C36: Hyperthermia (mEHT) 2
C37: mEHT 2 Treatment commencement | D37: =R4 -> 45961 | I37: =IF(I4=$D$37,1,0) -> 0 | J37: =IF(J4>=$D$37,1,0) -> 0 | K37: =IF(K4>=$D$37,1,0) -> 0 | L37: =IF(L4>=$D$37,1,0) -> 0 | M37: =IF(M4>=$D$37,1,0) -> 0 | N37: =IF(N4>=$D$37,1,0) -> 0 | O37: =IF(O4>=$D$37,1,0) -> 0 | P37: =IF(P4>=$D$37,1,0) -> 0 | Q37: =IF(Q4>=$D$37,1,0) -> 0 | ... BD37: =IF(BD4>=$D$37,1,0) -> 1
D38: Min | E38: Max | F38: Growth Rate
C39: mEHT 2 Number of Sessions | D39: 30 | E39: 208 | F39: 0.05 | I39: =MIN(MAX($D39,H39)*(1+$F39)*I$37,$E39) -> 0 | J39: =MIN(MAX($D39,I39)*(1+$F39)*J$37,$E39) -> 0 | K39: =MIN(MAX($D39,J39)*(1+$F39)*K$37,$E39) -> 0 | L39: =MIN(MAX($D39,K39)*(1+$F39)*L$37,$E39) -> 0 | M39: =MIN(MAX($D39,L39)*(1+$F39)*M$37,$E39) -> 0 | N39: =MIN(MAX($D39,M39)*(1+$F39)*N$37,$E39) -> 0 | O39: =MIN(MAX($D39,N39)*(1+$F39)*O$37,$E39) -> 0 | P39: =MIN(MAX($D39,O39)*(1+$F39)*P$37,$E39) -> 0 | ... BD39: =MIN(MAX($D39,BC39)*(1+$F39)*BD$37,$E39) -> 201.14253
C40: Average Revenue / Session | D40: 3555 | E40: 3555 | F40: 0 | I40: =MIN(MAX($D40,H40)*(1+$F40)*I$37,$E40) -> 0 | J40: =MIN(MAX($D40,I40)*(1+$F40)*J$37,$E40) -> 0 | K40: =MIN(MAX($D40,J40)*(1+$F40)*K$37,$E40) -> 0 | L40: =MIN(MAX($D40,K40)*(1+$F40)*L$37,$E40) -> 0 | M40: =MIN(MAX($D40,L40)*(1+$F40)*M$37,$E40) -> 0 | N40: =MIN(MAX($D40,M40)*(1+$F40)*N$37,$E40) -> 0 | O40: =MIN(MAX($D40,N40)*(1+$F40)*O$37,$E40) -> 0 | P40: =MIN(MAX($D40,O40)*(1+$F40)*P$37,$E40) -> 0 | ... BD40: =MIN(MAX($D40,BC40)*(1+$F40)*BD$37,$E40) -> 3555
C41: Hyperthermia 2 Session Revenue | I41: =I39*I40 -> 0 | J41: =J39*J40 -> 0 | K41: =K39*K40 -> 0 | L41: =L39*L40 -> 0 | M41: =M39*M40 -> 0 | N41: =N39*N40 -> 0 | O41: =O39*O40 -> 0 | P41: =P39*P40 -> 0 | ... BD41: =BD39*BD40 -> 715061.71
C43: HBOT 1
C44: HBOT 1 Sessions commencement | D44: =T4 -> 46022 | I44: =IF(I4>=$D$44,1,0) -> 0 | J44: =IF(J4>=$D$44,1,0) -> 0 | K44: =IF(K4>=$D$44,1,0) -> 0 | L44: =IF(L4>=$D$44,1,0) -> 0 | M44: =IF(M4>=$D$44,1,0) -> 0 | N44: =IF(N4>=$D$44,1,0) -> 0 | O44: =IF(O4>=$D$44,1,0) -> 0 | P44: =IF(P4>=$D$44,1,0) -> 0 | ... BD44: =IF(BD4>=$D$44,1,0) -> 1
E45: Max | F45: Growth Rate
C46: HBOT 1 Number of Sessions | D46: 16 | E46: 120 | F46: 0.05 | I46: =MIN(MAX($D46,H46)*(1+$F46)*I$44,$E46) -> 0 | J46: =MIN(MAX($D46,I46)*(1+$F46)*J$44,$E46) -> 0 | K46: =MIN(MAX($D46,J46)*(1+$F46)*K$44,$E46) -> 0 | L46: =MIN(MAX($D46,K46)*(1+$F46)*L$44,$E46) -> 0 | M46: =MIN(MAX($D46,L46)*(1+$F46)*M$44,$E46) -> 0 | N46: =MIN(MAX($D46,M46)*(1+$F46)*N$44,$E46) -> 0 | O46: =MIN(MAX($D46,N46)*(1+$F46)*O$44,$E46) -> 0 | P46: =MIN(MAX($D46,O46)*(1+$F46)*P$44,$E46) -> 0 | ... BD46: =MIN(MAX($D46,BC46)*(1+$F46)*BD$44,$E46) -> 97.302511
C47: Average Revenue / Session | D47: 2500 | E47: 2500 | F47: 0 | I47: =MIN(MAX($D47,H47)*(1+$F47)*I$44,$E47) -> 0 | J47: =MIN(MAX($D47,I47)*(1+$F47)*J$44,$E47) -> 0 | K47: =MIN(MAX($D47,J47)*(1+$F47)*K$44,$E47) -> 0 | L47: =MIN(MAX($D47,K47)*(1+$F47)*L$44,$E47) -> 0 | M47: =MIN(MAX($D47,L47)*(1+$F47)*M$44,$E47) -> 0 | N47: =MIN(MAX($D47,M47)*(1+$F47)*N$44,$E47) -> 0 | O47: =MIN(MAX($D47,N47)*(1+$F47)*O$44,$E47) -> 0 | P47: =MIN(MAX($D47,O47)*(1+$F47)*P$44,$E47) -> 0 | ... BD47: =MIN(MAX($D47,BC47)*(1+$F47)*BD$44,$E47) -> 2500
C48: HBOT 1 Session Revenue | I48: =I46*I47 -> 0 | J48: =J46*J47 -> 0 | K48: =K46*K47 -> 0 | L48: =L46*L47 -> 0 | M48: =M46*M47 -> 0 | N48: =N46*N47 -> 0 | O48: =O46*O47 -> 0 | P48: =P46*P47 -> 0 | ... BD48: =BD46*BD47 -> 243256.28
C50: HBOT 2
C51: HBOT 2 Sessions commencement | D51: 0 | I51: =IF(I4>=$D$51,1,0) -> 1 | J51: =IF(J4>=$D$51,1,0) -> 1 | K51: =IF(K4>=$D$51,1,0) -> 1 | L51: =IF(L4>=$D$51,1,0) -> 1 | M51: =IF(M4>=$D$51,1,0) -> 1 | N51: =IF(N4>=$D$51,1,0) -> 1 | O51: =IF(O4>=$D$51,1,0) -> 1 | P51: =IF(P4>=$D$51,1,0) -> 1 | ... BD51: =IF(BD4>=$D$51,1,0) -> 1
D52: Min | E52: Max | F52: Growth Rate
...

Sheet UK P & L
A1: Profit and Loss | K1: Sales by Item
A2: Sanctura Limited | K2: Sanctura Limited
A3: For the month ended 30 November 2025 | K3: 1 November 2025 to 30 November 2025
A5: Account | B5: Actual Nov 2025 | C5: Reforecast Nov 2025 | E5: Year to date | F5: Reforecast YTD | K5: Item | L5: Current Unit Price | M5: Quantity Sold | N5: Total | O5: Average Price
A7: Turnover | K7: Consultation - 1 hour (CON1) | L7: 510 | M7: 1 | N7: 500 | O7: =IF(ISERROR(N7/M7),"",N7/M7) -> 500
A8: Sales | B8: 87974 | C8: ='UK V4'!W260 -> 136170.11 | E8: 492815 | F8: =SUM('UK V4'!O260:W260) -> 753524.19 | K8: Consultation - 15 Minutes (CON6) | L8: 195 | M8: 17 | N8: 3315 | O8: =IF(ISERROR(N8/M8),"",N8/M8) -> 195
A9: Sales - Pathology | B9: 3711 | E9: 5250 | K9: Consultation - 30 min (CON2) | L9: 375 | M9: 27 | N9: 9750 | O9: =IF(ISERROR(N9/M9),"",N9/M9) -> 361.11111
A10: Agency Fees | B10: 210 | E10: 180625 | K10: Endovascular laser therapy - 20Min (ENDO) | L10: 100 | M10: 40 | N10: 4000 | O10: =IF(ISERROR(N10/M10),"",N10/M10) -> 100
A11: Total Turnover | B11: =SUM(B8:B10) -> 91895 | C11: =SUM(C8:C10) -> 136170.11 | E11: =SUM(E8:E10) -> 678690 | F11: =SUM(F8:F10) -> 753524.19 | K11: Hyperbaric Oxygen Therapy Session - 2 ATA 90 Min (HBOT) | L11: 200 | M11: 22 | N11: 4400 | O11: =IF(ISERROR(N11/M11),"",N11/M11) -> 200
K12: Infusion Fee (CON4) | L12: 125 | M12: 70 | N12: 8375 | O12: =IF(ISERROR(N12/M12),"",N12/M12) -> 119.64286
A13: Cost of Sales | K13: mEHT Hyperthermia Treatment - 60 Min (mEHT 60) | L13: 300 | M13: 22 | N13: 5400 | O13: =IF(ISERROR(N13/M13),"",N13/M13) -> 245.45455
A14: Cost of Goods Sold | B14: 7302 | C14: =-SUM('UK V4'!W262:W268) -> 16976.091 | E14: 68706 | F14: =-SUM('UK V4'!O262:W268) -> 102454.28 | K14: mEHT Hyperthermia Treatment - 90 Min (mEHT 90) | L14: 450 | M14: 59 | N14: 24970 | O14: =IF(ISERROR(N14/M14),"",N14/M14) -> 423.22034
A15: Pathology COS | B15: 0 | E15: 1250 | K15: Phlebotomy Fee (CON9) | L15: 69 | M15: 1 | N15: 69 | O15: =IF(ISERROR(N15/M15),"",N15/M15) -> 69
A16: Agency Fees COS | B16: 2557 | E16: 176565 | K16: Pathology Fees | N16: 3711.48
A17: Total Cost of Sales | B17: =SUM(B14:B16) -> 9859 | C17: =SUM(C14:C16) -> 16976.091 | E17: =SUM(E14:E16) -> 246521 | F17: =SUM(F14:F16) -> 102454.28 | K17: Transcranial Photobiomodulation (HEL) | L17: 50 | M17: 3 | N17: 150 | O17: =IF(ISERROR(N17/M17),"",N17/M17) -> 50
K18: Total | M18: =SUM(M7:M17) -> 262 | N18: =SUM(N7:N17) -> 64640.48 | O18: =IF(ISERROR(N18/M18),"",N18/M18) -> 246.71939
A19: Gross Profit | B19: =(B11 - B17) -> 82036 | C19: =(C11 - C17) -> 119194.02 | E19: =(E11 - E17) -> 432169 | F19: =(F11 - F17) -> 651069.92
K20: Summary
K21: Sales by item | N21: =N18 -> 64640.48
A22: Staff Costs: Medical, Admin, Consultants, Director | B22: =SUM(B41:B45) -> 44294.28 | C22: =-'UK V4'!W280 -> 60171.132 | E22: =SUM(E41:E45) -> 202536.9 | F22: =-SUM('UK V4'!O280:W280) -> 332362.73 | K22: Other sales | N22: =27044.56+375 -> 27419.56
A23: Rent | B23: =B66 -> 23750 | C23: =-'UK V4'!W282 -> 28500 | E23: =E66 -> 213750 | F23: =-SUM('UK V4'!O282:W282) -> 133995 | K23: Agency Fees | N23: 209.7
A24: Business rates, service charge, water and elec | B24: =B68 -> 13250.62 | C24: =-'UK V4'!W283 -> 16589 | E24: =E68 -> 114639.98 | F24: =-SUM('UK V4'!O283:W283) -> 128667 | K24: Credits | N24: -375
A25: Opex | B25: =SUM(B46:B64) -> 14408.33 | C25: =-'UK V4'!W286-'UK V4'!W288 -> 12000 | E25: =SUM(E46:E64) -> 93650.69 | F25: =-SUM('UK V4'!O286:W286)-SUM('UK V4'!O288:W288) -> 87782 | K25: Total Sales | N25: =SUM(N21:N24) -> 91894.74
A26: Realised and Unrealised Currency Gains | B26: =B65+B67 -> 101.87 | C26: 0 | E26: =E65+E67 -> 768.6
A27: Total Administrative Costs | B27: =SUM(B22:B26) -> 95805.1 | C27: =SUM(C22:C26) -> 117260.13 | E27: =SUM(E22:E26) -> 625346.17 | F27: =SUM(F22:F26) -> 682806.73
A29: Operating Profit | B29: =B19-B27 -> -13769.1 | C29: =C19-C27 -> 1933.8919 | E29: =E19-E27 -> -193177.17 | F29: =F19-F27 -> -31736.813
A31: Other Income
A32: Discount Received | B32: 0 | C32: 0 | E32: 633.41
A33: Total Other Income | B33: =B32 -> 0 | E33: =E32 -> 633.41
A35: Profit on Ordinary Activities Before Taxation | B35: =(B29 + B33) -> -13769.1 | E35: =(E29 + E33) -> -192543.76
A37: Profit after Taxation | B37: =(B35 - 0) -> -13769.1 | E37: =(E35 - 0) -> -192543.76
A39: Breakdown of Opex from P&L
A40: Administrative Costs
A41: Consulting, Accounting and Administrative Fees | B41: 21305 | E41: 63379.22
A42: Directors' Remuneration | B42: 3775 | E42: 33975
A43: Salaries | B43: 13986.94 | E43: 70175.98
A44: PAYE | B44: 4918.12 | E44: 32847.28
A45: Pension | B45: 309.22 | E45: 2159.42
A46: Advertising & Marketing | B46: 0 | E46: 1000
A47: Bank Fees | B47: 924.51 | E47: 2474.3
...

Sheet UK V4
J1: =YEAR(J3) -> 2024 | K1: =YEAR(K3) -> 2024 | L1: =YEAR(L3) -> 2024 | M1: =YEAR(M3) -> 2025 | N1: =YEAR(N3) -> 2025 | O1: =YEAR(O3) -> 2025 | P1: =YEAR(P3) -> 2025 | Q1: =YEAR(Q3) -> 2025 | ... BH1: =YEAR(BH3) -> 2028
C2: Total Company Cash Flow | D2: =D$331 -> -715914.82 | E2: =E$331 -> -1271416.8 | F2: =F$331 -> 417810.76 | G2: =G$331 -> 1711821.7 | H2: =H$331 -> 2670817.4 | J2: Actual | K2: Actual | L2: Actual | M2: Actuals | N2: Actuals | O2: Actuals | P2: Actuals | Q2: Actuals | R2: Actuals | S2: Actuals | T2: Forecast
C3: GBP | D3: 2024 | E3: =D3+1 -> 2025 | F3: =E3+1 -> 2026 | G3: =F3+1 -> 2027 | H3: =G3+1 -> 2028 | J3: 45596 | K3: =EOMONTH(J3,1) -> 45626 | L3: =EOMONTH(K3,1) -> 45657 | M3: =EOMONTH(L3,1) -> 45688 | N3: =EOMONTH(M3,1) -> 45716 | O3: =EOMONTH(N3,1) -> 45747 | P3: =EOMONTH(O3,1) -> 45777 | Q3: =EOMONTH(P3,1) -> 45808 | R3: =EOMONTH(Q3,1) -> 45838 | ... BH3: =EOMONTH(BG3,1) -> 47118
B4: ASSUMPTIONS
B6: Revenue Assumptions
C8: Treatment commencement | D8: =R3 -> 45838 | J8: =IF(J3>=$D$8,1,0) -> 0 | K8: =IF(K3>=$D$8,1,0) -> 0 | L8: =IF(L3>=$D$8,1,0) -> 0 | M8: =IF(M3>=$D$8,1,0) -> 0 | N8: =IF(N3>=$D$8,1,0) -> 0 | O8: =IF(O3>=$D$8,1,0) -> 0 | P8: =IF(P3>=$D$8,1,0) -> 0 | Q8: =IF(Q3>=$D$8,1,0) -> 0 | ... BH8: =IF(BH3>=$D$8,1,0) -> 1
C11: IV Treatments | D11: Min | E11: Max | F11: Growth Rate
C12: IV Number of Treatments | D12: 30 | E12: 320 | F12: 0.075 | J12: 0 | K12: 0 | L12: 0 | M12: 0 | N12: 0 | O12: 0 | P12: 0 | Q12: 0 | R12: 13 | S12: 16 | T12: =MIN(MAX($D12,S12)*(1+$F12)*T$8,$E12) -> 32.25 | U12: =MIN(MAX($D12,T12)*(1+$F12)*U$8,$E12) -> 34.66875 | V12: =MIN(MAX($D12,U12)*(1+$F12)*V$8,$E12) -> 37.268906 | W12: =MIN(MAX($D12,V12)*(1+$F12)*W$8,$E12) -> 40.064074 | X12: =MIN(MAX($D12,W12)*(1+$F12)*X$8,$E12) -> 43.06888 | Y12: =MIN(MAX($D12,X12)*(1+$F12)*Y$8,$E12) -> 46.299046 | Z12: =MIN(MAX($D12,Y12)*(1+$F12)*Z$8,$E12) -> 49.771474 | AA12: =MIN(MAX($D12,Z12)*(1+$F12)*AA$8,$E12) -> 53.504335 | ... BH12: =MIN(MAX($D12,BG12)*(1+$F12)*BH$8,$E12) -> 320
C13: Average Revenue / Treatment | D13: 450 | E13: 500 | F13: 0.02 | J13: =MIN(MAX($D13,I13)*(1+$F13)*J$8,$E13) -> 0 | K13: =MIN(MAX($D13,J13)*(1+$F13)*K$8,$E13) -> 0 | L13: =MIN(MAX($D13,K13)*(1+$F13)*L$8,$E13) -> 0 | M13: =MIN(MAX($D13,L13)*(1+$F13)*M$8,$E13) -> 0 | N13: =MIN(MAX($D13,M13)*(1+$F13)*N$8,$E13) -> 0 | O13: =MIN(MAX($D13,N13)*(1+$F13)*O$8,$E13) -> 0 | P13: =MIN(MAX($D13,O13)*(1+$F13)*P$8,$E13) -> 0 | Q13: =MIN(MAX($D13,P13)*(1+$F13)*Q$8,$E13) -> 0 | R13: 609 | S13: 474 | T13: =MIN(MAX($D13,S13)*(1+$F13)*T$8,$E13) -> 483.48 | U13: =MIN(MAX($D13,T13)*(1+$F13)*U$8,$E13) -> 493.1496 | V13: =MIN(MAX($D13,U13)*(1+$F13)*V$8,$E13) -> 500 | W13: =MIN(MAX($D13,V13)*(1+$F13)*W$8,$E13) -> 500 | X13: =MIN(MAX($D13,W13)*(1+$F13)*X$8,$E13) -> 500 | Y13: =MIN(MAX($D13,X13)*(1+$F13)*Y$8,$E13) -> 500 | Z13: =MIN(MAX($D13,Y13)*(1+$F13)*Z$8,$E13) -> 500 | AA13: =MIN(MAX($D13,Z13)*(1+$F13)*AA$8,$E13) -> 500 | ... BH13: =MIN(MAX($D13,BG13)*(1+$F13)*BH$8,$E13) -> 500
C14: IV Treatment Revenue | J14: =J12*J13 -> 0 | K14: =K12*K13 -> 0 | L14: =L12*L13 -> 0 | M14: =M12*M13 -> 0 | N14: =N12*N13 -> 0 | O14: =O12*O13 -> 0 | P14: =P12*P13 -> 0 | Q14: =Q12*Q13 -> 0 | ... BH14: =BH12*BH13 -> 160000
C16: IV COS | D16: =-D13*0.3 -> -135 | J16: =-J14*0.4 -> 0 | K16: =-K14*0.4 -> 0 | L16: =-L14*0.4 -> 0 | M16: =-M14*0.4 -> 0 | N16: =-N14*0.4 -> 0 | O16: =-O14*0.4 -> 0 | P16: =-P14*0.4 -> 0 | Q16: =-Q14*0.4 -> 0 | ... S16: =-S14*0.4 -> -3033.6 | T16: =T12*$D16 -> -4353.75 | U16: =U12*$D16 -> -4680.2812 | V16: =V12*$D16 -> -5031.3023 | W16: =W12*$D16 -> -5408.65 | X16: =X12*$D16 -> -5814.2988 | Y16: =Y12*$D16 -> -6250.3712 | Z16: =Z12*$D16 -> -6719.149 | AA16: =AA12*$D16 -> -7223.0852 | ... BH16: =BH12*$D16 -> -43200
C18: IV Curcumin 100mg Treatments | D18: Min | E18: Max | F18: Growth Rate
C19: IV Curcumin 100mg Number of Treatments | D19: 10 | E19: 80 | F19: 0.025 | J19: 0 | K19: 0 | L19: 0 | M19: 0 | N19: 0 | O19: 0 | P19: 0 | Q19: 27 | R19: 22 | S19: 37 | T19: =MIN(MAX($D19,S19)*(1+$F19)*T$8,$E19) -> 37.925 | U19: =MIN(MAX($D19,T19)*(1+$F19)*U$8,$E19) -> 38.873125 | V19: =MIN(MAX($D19,U19)*(1+$F19)*V$8,$E19) -> 39.844953 | W19: =MIN(MAX($D19,V19)*(1+$F19)*W$8,$E19) -> 40.841077 | X19: =MIN(MAX($D19,W19)*(1+$F19)*X$8,$E19) -> 41.862104 | Y19: =MIN(MAX($D19,X19)*(1+$F19)*Y$8,$E19) -> 42.908656 | Z19: =MIN(MAX($D19,Y19)*(1+$F19)*Z$8,$E19) -> 43.981373 | AA19: =MIN(MAX($D19,Z19)*(1+$F19)*AA$8,$E19) -> 45.080907 | ... BH19: =MIN(MAX($D19,BG19)*(1+$F19)*BH$8,$E19) -> 80
C20: Average Revenue / Treatment | D20: 375 | E20: 375 | F20: 0 | J20: =MIN(MAX($D20,I20)*(1+$F20)*J$8,$E20) -> 0 | K20: =MIN(MAX($D20,J20)*(1+$F20)*K$8,$E20) -> 0 | L20: =MIN(MAX($D20,K20)*(1+$F20)*L$8,$E20) -> 0 | M20: =MIN(MAX($D20,L20)*(1+$F20)*M$8,$E20) -> 0 | N20: =MIN(MAX($D20,M20)*(1+$F20)*N$8,$E20) -> 0 | O20: =MIN(MAX($D20,N20)*(1+$F20)*O$8,$E20) -> 0 | P20: =MIN(MAX($D20,O20)*(1+$F20)*P$8,$E20) -> 0 | Q20: 398.55 | R20: 276 | S20: 275 | T20: =MIN(MAX($D20,S20)*(1+$F20)*T$8,$E20) -> 375 | U20: =MIN(MAX($D20,T20)*(1+$F20)*U$8,$E20) -> 375 | V20: =MIN(MAX($D20,U20)*(1+$F20)*V$8,$E20) -> 375 | W20: =MIN(MAX($D20,V20)*(1+$F20)*W$8,$E20) -> 375 | X20: =MIN(MAX($D20,W20)*(1+$F20)*X$8,$E20) -> 375 | Y20: =MIN(MAX($D20,X20)*(1+$F20)*Y$8,$E20) -> 375 | Z20: =MIN(MAX($D20,Y20)*(1+$F20)*Z$8,$E20) -> 375 | AA20: =MIN(MAX($D20,Z20)*(1+$F20)*AA$8,$E20) -> 375 | ... BH20: =MIN(MAX($D20,BG20)*(1+$F20)*BH$8,$E20) -> 375
C21: IV Currcumin 100mg Treatment Revenue | J21: =J19*J20 -> 0 | K21: =K19*K20 -> 0 | L21: =L19*L20 -> 0 | M21: =M19*M20 -> 0 | N21: =N19*N20 -> 0 | O21: =O19*O20 -> 0 | P21: =P19*P20 -> 0 | Q21: =Q19*Q20 -> 10760.85 | ... BH21: =BH19*BH20 -> 30000
C23: IV Curcumin 100mg COS | D23: =-D20*0.3 -> -112.5 | J23: =-J21*0.4 -> 0 | K23: =-K21*0.4 -> 0 | L23: =-L21*0.4 -> 0 | M23: =-M21*0.4 -> 0 | N23: =-N21*0.4 -> 0 | O23: =-O21*0.4 -> 0 | P23: =-P21*0.4 -> 0 | Q23: =-Q21*0.4 -> -4304.34 | ... S23: =-S21*0.4 -> -4070 | T23: =T19*$D23 -> -4266.5625 | U23: =U19*$D23 -> -4373.2266 | V23: =V19*$D23 -> -4482.5572 | W23: =W19*$D23 -> -4594.6212 | X23: =X19*$D23 -> -4709.4867 | Y23: =Y19*$D23 -> -4827.2239 | Z23: =Z19*$D23 -> -4947.9044 | AA23: =AA19*$D23 -> -5071.6021 | ... BH23: =BH19*$D23 -> -9000
C25: Laser Treatments | D25: Min | E25: Max | F25: Growth Rate
C26: Laser Number of Treatments | D26: 17 | E26: 350 | F26: 0.05 | J26: 0 | K26: 0 | L26: 0 | M26: 0 | N26: 0 | O26: 0 | P26: 0 | Q26: 5 | R26: 17 | S26: 19 | T26: =MIN(MAX($D26,S26)*(1+$F26)*T$8,$E26) -> 19.95 | U26: =MIN(MAX($D26,T26)*(1+$F26)*U$8,$E26) -> 20.9475 | V26: =MIN(MAX($D26,U26)*(1+$F26)*V$8,$E26) -> 21.994875 | W26: =MIN(MAX($D26,V26)*(1+$F26)*W$8,$E26) -> 23.094619 | X26: =MIN(MAX($D26,W26)*(1+$F26)*X$8,$E26) -> 24.24935 | Y26: =MIN(MAX($D26,X26)*(1+$F26)*Y$8,$E26) -> 25.461817 | Z26: =MIN(MAX($D26,Y26)*(1+$F26)*Z$8,$E26) -> 26.734908 | AA26: =MIN(MAX($D26,Z26)*(1+$F26)*AA$8,$E26) -> 28.071653 | ... BH26: =MIN(MAX($D26,BG26)*(1+$F26)*BH$8,$E26) -> 140.44777
C27: Average Revenue / Treatment | D27: 100 | E27: 150 | F27: 0 | J27: =MIN(MAX($D27,I27)*(1+$F27)*J$8,$E27) -> 0 | K27: =MIN(MAX($D27,J27)*(1+$F27)*K$8,$E27) -> 0 | L27: =MIN(MAX($D27,K27)*(1+$F27)*L$8,$E27) -> 0 | M27: =MIN(MAX($D27,L27)*(1+$F27)*M$8,$E27) -> 0 | N27: =MIN(MAX($D27,M27)*(1+$F27)*N$8,$E27) -> 0 | O27: =MIN(MAX($D27,N27)*(1+$F27)*O$8,$E27) -> 0 | P27: =MIN(MAX($D27,O27)*(1+$F27)*P$8,$E27) -> 0 | Q27: 84 | R27: 100 | S27: 100 | T27: =MIN(MAX($D27,S27)*(1+$F27)*T$8,$E27) -> 100 | U27: =MIN(MAX($D27,T27)*(1+$F27)*U$8,$E27) -> 100 | V27: =MIN(MAX($D27,U27)*(1+$F27)*V$8,$E27) -> 100 | W27: =MIN(MAX($D27,V27)*(1+$F27)*W$8,$E27) -> 100 | X27: =MIN(MAX($D27,W27)*(1+$F27)*X$8,$E27) -> 100 | Y27: =MIN(MAX($D27,X27)*(1+$F27)*Y$8,$E27) -> 100 | Z27: =MIN(MAX($D27,Y27)*(1+$F27)*Z$8,$E27) -> 100 | AA27: =MIN(MAX($D27,Z27)*(1+$F27)*AA$8,$E27) -> 100 | ... BH27: =MIN(MAX($D27,BG27)*(1+$F27)*BH$8,$E27) -> 100
C28: Laser Patient Revenue | J28: =J26*J27 -> 0 | K28: =K26*K27 -> 0 | L28: =L26*L27 -> 0 | M28: =M26*M27 -> 0 | N28: =N26*N27 -> 0 | O28: =O26*O27 -> 0 | P28: =P26*P27 -> 0 | Q28: =Q26*Q27 -> 420 | ... BH28: =BH26*BH27 -> 14044.777
C30: Hyperthermia (mEHT) 1 | D30: Min | E30: Max | F30: Growth Rate
C31: mEHT Number of Sessions | D31: 60 | E31: 173 | F31: 0.05 | J31: 0 | K31: 0 | L31: 0 | M31: 0 | N31: 0 | O31: 0 | P31: 0 | Q31: 5 | R31: 58 | S31: 62 | T31: 78 | U31: 117 | V31: =MIN(MAX($D31,U31)*(1+$F31)*V$8,$E31) -> 122.85 | W31: =MIN(MAX($D31,V31)*(1+$F31)*W$8,$E31) -> 128.9925 | X31: =MIN(MAX($D31,W31)*(1+$F31)*X$8,$E31) -> 135.44213 | Y31: =MIN(MAX($D31,X31)*(1+$F31)*Y$8,$E31) -> 142.21423 | Z31: =MIN(MAX($D31,Y31)*(1+$F31)*Z$8,$E31) -> 149.32494 | AA31: =MIN(MAX($D31,Z31)*(1+$F31)*AA$8,$E31) -> 156.79119 | AB31: =MIN(MAX($D31,AA31)*(1+$F31)*AB$8,$E31) -> 164.63075 | AC31: =MIN(MAX($D31,AB31)*(1+$F31)*AC$8,$E31) -> 172.86229 | ... BH31: =MIN(MAX($D31,BG31)*(1+$F31)*BH$8,$E31) -> 173
C32: Average Revenue / Session | D32: 300 | E32: 450 | F32: 0 | J32: 0 | K32: 0 | L32: 0 | M32: 0 | N32: 0 | O32: 0 | P32: 0 | Q32: 300 | R32: 292 | S32: 300 | T32: =MIN(MAX($D32,S32)*(1+$F32)*T$8,$E32) -> 300 | U32: =MIN(MAX($D32,T32)*(1+$F32)*U$8,$E32) -> 300 | V32: =MIN(MAX($D32,U32)*(1+$F32)*V$8,$E32) -> 300 | W32: =MIN(MAX($D32,V32)*(1+$F32)*W$8,$E32) -> 300 | X32: =MIN(MAX($D32,W32)*(1+$F32)*X$8,$E32) -> 300 | Y32: =MIN(MAX($D32,X32)*(1+$F32)*Y$8,$E32) -> 300 | Z32: =MIN(MAX($D32,Y32)*(1+$F32)*Z$8,$E32) -> 300 | AA32: =MIN(MAX($D32,Z32)*(1+$F32)*AA$8,$E32) -> 300 | ... BH32: =MIN(MAX($D32,BG32)*(1+$F32)*BH$8,$E32) -> 300
C33: Hyperthermia Session Revenue | J33: =J31*J32 -> 0 | K33: =K31*K32 -> 0 | L33: =L31*L32 -> 0 | M33: =M31*M32 -> 0 | N33: =N31*N32 -> 0 | O33: =O31*O32 -> 0 | P33: =P31*P32 -> 0 | Q33: =Q31*Q32 -> 1500 | ... BH33: =BH31*BH32 -> 51900
C35: Hyperthermia (mEHT) 2
C36: mEHT 2 Treatment commencement | D36: =V3 -> 45961 | J36: =IF(J3=$D$36,1,0) -> 0 | K36: =IF(K3>=$D$36,1,0) -> 0 | L36: =IF(L3>=$D$36,1,0) -> 0 | M36: =IF(M3>=$D$36,1,0) -> 0 | N36: =IF(N3>=$D$36,1,0) -> 0 | O36: =IF(O3>=$D$36,1,0) -> 0 | P36: =IF(P3>=$D$36,1,0) -> 0 | Q36: =IF(Q3>=$D$36,1,0) -> 0 | R36: =IF(R3>=$D$36,1,0) -> 0 | ... BH36: =IF(BH3>=$D$36,1,0) -> 1
D37: Min | E37: Max | F37: Growth Rate
C38: mEHT 2 Number of Sessions | D38: 60 | E38: 173 | F38: 0.05 | J38: 0 | K38: 0 | L38: 0 | M38: 0 | N38: 0 | O38: 0 | P38: 0 | Q38: 0 | R38: 0 | S38: 0 | T38: 0 | U38: 0 | V38: 62 | W38: 78 | X38: 117 | Y38: =MIN(MAX($D38,X38)*(1+$F38)*Y$36,$E38) -> 122.85 | Z38: =MIN(MAX($D38,Y38)*(1+$F38)*Z$36,$E38) -> 128.9925 | AA38: =MIN(MAX($D38,Z38)*(1+$F38)*AA$36,$E38) -> 135.44213 | AB38: =MIN(MAX($D38,AA38)*(1+$F38)*AB$36,$E38) -> 142.21423 | AC38: =MIN(MAX($D38,AB38)*(1+$F38)*AC$36,$E38) -> 149.32494 | AD38: =MIN(MAX($D38,AC38)*(1+$F38)*AD$36,$E38) -> 156.79119 | AE38: =MIN(MAX($D38,AD38)*(1+$F38)*AE$36,$E38) -> 164.63075 | AF38: =MIN(MAX($D38,AE38)*(1+$F38)*AF$36,$E38) -> 172.86229 | ... BH38: =MIN(MAX($D38,BG38)*(1+$F38)*BH$36,$E38) -> 173
C39: Average Revenue / Session | D39: 300 | E39: 450 | F39: 0 | J39: =MIN(MAX($D39,I39)*(1+$F39)*J$36,$E39) -> 0 | K39: =MIN(MAX($D39,J39)*(1+$F39)*K$36,$E39) -> 0 | L39: =MIN(MAX($D39,K39)*(1+$F39)*L$36,$E39) -> 0 | M39: =MIN(MAX($D39,L39)*(1+$F39)*M$36,$E39) -> 0 | N39: =MIN(MAX($D39,M39)*(1+$F39)*N$36,$E39) -> 0 | O39: =MIN(MAX($D39,N39)*(1+$F39)*O$36,$E39) -> 0 | P39: =MIN(MAX($D39,O39)*(1+$F39)*P$36,$E39) -> 0 | Q39: =MIN(MAX($D39,P39)*(1+$F39)*Q$36,$E39) -> 0 | ... BH39: =MIN(MAX($D39,BG39)*(1+$F39)*BH$36,$E39) -> 300
C40: Hyperthermia 2 Session Revenue | J40: =J38*J39 -> 0 | K40: =K38*K39 -> 0 | L40: =L38*L39 -> 0 | M40: =M38*M39 -> 0 | N40: =N38*N39 -> 0 | O40: =O38*O39 -> 0 | P40: =P38*P39 -> 0 | Q40: =Q38*Q39 -> 0 | ... BH40: =BH38*BH39 -> 51900
C42: HBOT 1
C43: HBOT 1 Sessions commencement | D43: =T3 -> 45900 | J43: =IF(J3>=$D$43,1,0) -> 0 | K43: =IF(K3>=$D$43,1,0) -> 0 | L43: =IF(L3>=$D$43,1,0) -> 0 | M43: =IF(M3>=$D$43,1,0) -> 0 | N43: =IF(N3>=$D$43,1,0) -> 0 | O43: =IF(O3>=$D$43,1,0) -> 0 | P43: =IF(P3>=$D$43,1,0) -> 0 | Q43: =IF(Q3>=$D$43,1,0) -> 0 | ... BH43: =IF(BH3>=$D$43,1,0) -> 1
D44: Min | E44: Max | F44: Growth Rate
C45: HBOT 1 Number of Sessions | D45: 20 | E45: 120 | F45: 0.1 | J45: =MIN(MAX($D45,I45)*(1+$F45)*J$43,$E45) -> 0 | K45: =MIN(MAX($D45,J45)*(1+$F45)*K$43,$E45) -> 0 | L45: =MIN(MAX($D45,K45)*(1+$F45)*L$43,$E45) -> 0 | M45: =MIN(MAX($D45,L45)*(1+$F45)*M$43,$E45) -> 0 | N45: =MIN(MAX($D45,M45)*(1+$F45)*N$43,$E45) -> 0 | O45: =MIN(MAX($D45,N45)*(1+$F45)*O$43,$E45) -> 0 | P45: =MIN(MAX($D45,O45)*(1+$F45)*P$43,$E45) -> 0 | Q45: =MIN(MAX($D45,P45)*(1+$F45)*Q$43,$E45) -> 0 | R45: =MIN(MAX($D45,Q45)*(1+$F45)*R$43,$E45) -> 0 | S45: 1 | T45: =MIN(MAX($D45,S45)*(1+$F45)*T$43,$E45) -> 22 | U45: =MIN(MAX($D45,T45)*(1+$F45)*U$43,$E45) -> 24.2 | V45: =MIN(MAX($D45,U45)*(1+$F45)*V$43,$E45) -> 26.62 | W45: =MIN(MAX($D45,V45)*(1+$F45)*W$43,$E45) -> 29.282 | X45: =MIN(MAX($D45,W45)*(1+$F45)*X$43,$E45) -> 32.2102 | Y45: =MIN(MAX($D45,X45)*(1+$F45)*Y$43,$E45) -> 35.43122 | Z45: =MIN(MAX($D45,Y45)*(1+$F45)*Z$43,$E45) -> 38.974342 | AA45: =MIN(MAX($D45,Z45)*(1+$F45)*AA$43,$E45) -> 42.871776 | ... BH45: =MIN(MAX($D45,BG45)*(1+$F45)*BH$43,$E45) -> 120
C46: Average Revenue / Session | D46: 200 | E46: 200 | F46: 0 | J46: =MIN(MAX($D46,I46)*(1+$F46)*J$43,$E46) -> 0 | K46: =MIN(MAX($D46,J46)*(1+$F46)*K$43,$E46) -> 0 | L46: =MIN(MAX($D46,K46)*(1+$F46)*L$43,$E46) -> 0 | M46: =MIN(MAX($D46,L46)*(1+$F46)*M$43,$E46) -> 0 | N46: =MIN(MAX($D46,M46)*(1+$F46)*N$43,$E46) -> 0 | O46: =MIN(MAX($D46,N46)*(1+$F46)*O$43,$E46) -> 0 | P46: =MIN(MAX($D46,O46)*(1+$F46)*P$43,$E46) -> 0 | Q46: =MIN(MAX($D46,P46)*(1+$F46)*Q$43,$E46) -> 0 | R46: =MIN(MAX($D46,Q46)*(1+$F46)*R$43,$E46) -> 0 | S46: 200 | T46: =MIN(MAX($D46,S46)*(1+$F46)*T$43,$E46) -> 200 | U46: =MIN(MAX($D46,T46)*(1+$F46)*U$43,$E46) -> 200 | V46: =MIN(MAX($D46,U46)*(1+$F46)*V$43,$E46) -> 200 | W46: =MIN(MAX($D46,V46)*(1+$F46)*W$43,$E46) -> 200 | X46: =MIN(MAX($D46,W46)*(1+$F46)*X$43,$E46) -> 200 | Y46: =MIN(MAX($D46,X46)*(1+$F46)*Y$43,$E46) -> 200 | Z46: =MIN(MAX($D46,Y46)*(1+$F46)*Z$43,$E46) -> 200 | AA46: =MIN(MAX($D46,Z46)*(1+$F46)*AA$43,$E46) -> 200 | ... BH46: =MIN(MAX($D46,BG46)*(1+$F46)*BH$43,$E46) -> 200
C47: HBOT 1 Session Revenue | J47: =J45*J46 -> 0 | K47: =K45*K46 -> 0 | L47: =L45*L46 -> 0 | M47: =M45*M46 -> 0 | N47: =N45*N46 -> 0 | O47: =O45*O46 -> 0 | P47: =P45*P46 -> 0 | Q47: =Q45*Q46 -> 0 | ... BH47: =BH45*BH46 -> 24000
C49: HBOT 2
C50: HBOT 2 Sessions commencement | D50: 0 | J50: =IF(J3>=$D$50,1,0) -> 1 | K50: =IF(K3>=$D$50,1,0) -> 1 | L50: =IF(L3>=$D$50,1,0) -> 1 | M50: =IF(M3>=$D$50,1,0) -> 1 | N50: =IF(N3>=$D$50,1,0) -> 1 | O50: =IF(O3>=$D$50,1,0) -> 1 | P50: =IF(P3>=$D$50,1,0) -> 1 | Q50: =IF(Q3>=$D$50,1,0) -> 1 | ... BH50: =IF(BH3>=$D$50,1,0) -> 1
D51: Min | E51: Max | F51: Growth Rate
C52: HBOT 2 Number of Sessions | D52: 0 | E52: 0 | F52: 0 | J52: =MIN(MAX($D52,I52)*(1+$F52)*J$50,$E52) -> 0 | K52: =MIN(MAX($D52,J52)*(1+$F52)*K$50,$E52) -> 0 | L52: =MIN(MAX($D52,K52)*(1+$F52)*L$50,$E52) -> 0 | M52: =MIN(MAX($D52,L52)*(1+$F52)*M$50,$E52) -> 0 | N52: =MIN(MAX($D52,M52)*(1+$F52)*N$50,$E52) -> 0 | O52: =MIN(MAX($D52,N52)*(1+$F52)*O$50,$E52) -> 0 | P52: =MIN(MAX($D52,O52)*(1+$F52)*P$50,$E52) -> 0 | Q52: =MIN(MAX($D52,P52)*(1+$F52)*Q$50,$E52) -> 0 | ... BH52: =MIN(MAX($D52,BG52)*(1+$F52)*BH$50,$E52) -> 0
...
